Workbook

Sheet Sector-wise Analysis
A1: Sector | B1: Company | C1: Metric | D1: Year | E1: Value | F1: Type
A2: BFSI | B2: Axis Bank | C2: AUM | D2: 2020 | E2: ='[1]Balance Sheet-Banks'!$B$75 -> 582958.8 | F2: =IF(VALUE(D2)>2024,"Forecast","Actual") -> Actual
A3: BFSI | B3: Axis Bank | C3: AUM | D3: 2021 | E3: ='[1]Balance Sheet-Banks'!$C$75 -> 625749.9 | F3: =IF(VALUE(D3)>2024,"Forecast","Actual") -> Actual
A4: BFSI | B4: Axis Bank | C4: AUM | D4: 2022 | E4: ='[1]Balance Sheet-Banks'!$D$75 -> 725125.5 | F4: =IF(VALUE(D4)>2024,"Forecast","Actual") -> Actual
A5: BFSI | B5: Axis Bank | C5: AUM | D5: 2023 | E5: ='[1]Balance Sheet-Banks'!$E$75 -> 868387.54 | F5: =IF(VALUE(D5)>2024,"Forecast","Actual") -> Actual
A6: BFSI | B6: Axis Bank | C6: AUM | D6: 2024 | E6: ='[1]Balance Sheet-Banks'!$F$75 -> 999333.48 | F6: =IF(VALUE(D6)>2024,"Forecast","Actual") -> Actual
A7: BFSI | B7: Axis Bank | C7: AUM | D7: 2025 | E7: ='[1]Financial Projections'!$D$5 -> 1113076.3 | F7: =IF(VALUE(D7)>2024,"Forecast","Actual") -> Forecast
A8: BFSI | B8: Axis Bank | C8: AUM | D8: 2026 | E8: ='[1]Financial Projections'!$E$5 -> 1239765.3 | F8: =IF(VALUE(D8)>2024,"Forecast","Actual") -> Forecast
A9: BFSI | B9: Axis Bank | C9: AUM | D9: 2027 | E9: ='[1]Financial Projections'!$F$5 -> 1380873.8 | F9: =IF(VALUE(D9)>2024,"Forecast","Actual") -> Forecast
A10: BFSI | B10: Axis Bank | C10: AUM | D10: 2028 | E10: ='[1]Financial Projections'!$G$5 -> 1538043.1 | F10: =IF(VALUE(D10)>2024,"Forecast","Actual") -> Forecast
A11: BFSI | B11: Axis Bank | C11: AUM | D11: 2029 | E11: ='[1]Financial Projections'!$H$5 -> 1713101.2 | F11: =IF(VALUE(D11)>2024,"Forecast","Actual") -> Forecast
A12: BFSI | B12: Axis Bank | C12: AUM | D12: 2030 | E12: ='[1]Financial Projections'!$I$5 -> 1908084.2 | F12: =IF(VALUE(D12)>2024,"Forecast","Actual") -> Forecast
A13: BFSI | B13: HDFC Bank | C13: AUM | D13: 2020 | E13: ='[1]Balance Sheet-Banks'!$G$75 -> 1043670.8 | F13: =IF(VALUE(D13)>2024,"Forecast","Actual") -> Actual
A14: BFSI | B14: HDFC Bank | C14: AUM | D14: 2021 | E14: ='[1]Balance Sheet-Banks'!$H$75 -> 1185283.5 | F14: =IF(VALUE(D14)>2024,"Forecast","Actual") -> Actual
A15: BFSI | B15: HDFC Bank | C15: AUM | D15: 2022 | E15: ='[1]Balance Sheet-Banks'!$I$75 -> 1420942.3 | F15: =IF(VALUE(D15)>2024,"Forecast","Actual") -> Actual
A16: BFSI | B16: HDFC Bank | C16: AUM | D16: 2023 | E16: ='[1]Balance Sheet-Banks'!$J$75 -> 1661949.3 | F16: =IF(VALUE(D16)>2024,"Forecast","Actual") -> Actual
A17: BFSI | B17: HDFC Bank | C17: AUM | D17: 2024 | E17: ='[1]Balance Sheet-Banks'!$K$75 -> 2565891.4 | F17: =IF(VALUE(D17)>2024,"Forecast","Actual") -> Actual
A18: BFSI | B18: HDFC Bank | C18: AUM | D18: 2025 | E18: ='[1]Financial Projections'!$M$5 -> 3071660.5 | F18: =IF(VALUE(D18)>2024,"Forecast","Actual") -> Forecast
A19: BFSI | B19: HDFC Bank | C19: AUM | D19: 2026 | E19: ='[1]Financial Projections'!$N$5 -> 3677123 | F19: =IF(VALUE(D19)>2024,"Forecast","Actual") -> Forecast
A20: BFSI | B20: HDFC Bank | C20: AUM | D20: 2027 | E20: ='[1]Financial Projections'!$O$5 -> 4401929.7 | F20: =IF(VALUE(D20)>2024,"Forecast","Actual") -> Forecast
A21: BFSI | B21: HDFC Bank | C21: AUM | D21: 2028 | E21: ='[1]Financial Projections'!$P$5 -> 5269604.9 | F21: =IF(VALUE(D21)>2024,"Forecast","Actual") -> Forecast
A22: BFSI | B22: HDFC Bank | C22: AUM | D22: 2029 | E22: ='[1]Financial Projections'!$Q$5 -> 6308309.6 | F22: =IF(VALUE(D22)>2024,"Forecast","Actual") -> Forecast
A23: BFSI | B23: HDFC Bank | C23: AUM | D23: 2030 | E23: ='[1]Financial Projections'!$R$5 -> 7551755.9 | F23: =IF(VALUE(D23)>2024,"Forecast","Actual") -> Forecast
A24: BFSI | B24: ICICI Bank | C24: AUM | D24: 2020 | E24: ='[1]Balance Sheet-Banks'!$L$75 -> 706246.09 | F24: =IF(VALUE(D24)>2024,"Forecast","Actual") -> Actual
A25: BFSI | B25: ICICI Bank | C25: AUM | D25: 2021 | E25: ='[1]Balance Sheet-Banks'!$M$75 -> 733729.04 | F25: =IF(VALUE(D25)>2024,"Forecast","Actual") -> Actual
A26: BFSI | B26: ICICI Bank | C26: AUM | D26: 2022 | E26: ='[1]Balance Sheet-Banks'!$N$75 -> 859020.4 | F26: =IF(VALUE(D26)>2024,"Forecast","Actual") -> Actual
A27: BFSI | B27: ICICI Bank | C27: AUM | D27: 2023 | E27: ='[1]Balance Sheet-Banks'!$O$75 -> 1083866.3 | F27: =IF(VALUE(D27)>2024,"Forecast","Actual") -> Actual
A28: BFSI | B28: ICICI Bank | C28: AUM | D28: 2024 | E28: ='[1]Balance Sheet-Banks'!$P$75 -> 1260776.2 | F28: =IF(VALUE(D28)>2024,"Forecast","Actual") -> Actual
A29: BFSI | B29: ICICI Bank | C29: AUM | D29: 2025 | E29: ='[1]Financial Projections'!$V$5 -> 1415710.3 | F29: =IF(VALUE(D29)>2024,"Forecast","Actual") -> Forecast
A30: BFSI | B30: ICICI Bank | C30: AUM | D30: 2026 | E30: ='[1]Financial Projections'!$W$5 -> 1589683.9 | F30: =IF(VALUE(D30)>2024,"Forecast","Actual") -> Forecast
A31: BFSI | B31: ICICI Bank | C31: AUM | D31: 2027 | E31: ='[1]Financial Projections'!$X$5 -> 1785036.7 | F31: =IF(VALUE(D31)>2024,"Forecast","Actual") -> Forecast
A32: BFSI | B32: ICICI Bank | C32: AUM | D32: 2028 | E32: ='[1]Financial Projections'!$Y$5 -> 2004396.1 | F32: =IF(VALUE(D32)>2024,"Forecast","Actual") -> Forecast
A33: BFSI | B33: ICICI Bank | C33: AUM | D33: 2029 | E33: ='[1]Financial Projections'!$Z$5 -> 2250712 | F33: =IF(VALUE(D33)>2024,"Forecast","Actual") -> Forecast
A34: BFSI | B34: ICICI Bank | C34: AUM | D34: 2030 | E34: ='[1]Financial Projections'!$AA$5 -> 2527297.2 | F34: =IF(VALUE(D34)>2024,"Forecast","Actual") -> Forecast
A35: BFSI | B35: SBI | C35: AUM | D35: 2020 | E35: ='[1]Balance Sheet-Banks'!$Q$75 -> 2374311.2 | F35: =IF(VALUE(D35)>2024,"Forecast","Actual") -> Actual
A36: BFSI | B36: SBI | C36: AUM | D36: 2021 | E36: ='[1]Balance Sheet-Banks'!$R$75 -> 2500599 | F36: =IF(VALUE(D36)>2024,"Forecast","Actual") -> Actual
A37: BFSI | B37: SBI | C37: AUM | D37: 2022 | E37: ='[1]Balance Sheet-Banks'!$S$75 -> 2794076 | F37: =IF(VALUE(D37)>2024,"Forecast","Actual") -> Actual
A38: BFSI | B38: SBI | C38: AUM | D38: 2023 | E38: ='[1]Balance Sheet-Banks'!$T$75 -> 3267902.1 | F38: =IF(VALUE(D38)>2024,"Forecast","Actual") -> Actual
A39: BFSI | B39: SBI | C39: AUM | D39: 2024 | E39: ='[1]Balance Sheet-Banks'!$U$75 -> 3784272.7 | F39: =IF(VALUE(D39)>2024,"Forecast","Actual") -> Actual
A40: BFSI | B40: SBI | C40: AUM | D40: 2025 | E40: ='[1]Financial Projections'!$AE$5 -> 4154046.7 | F40: =IF(VALUE(D40)>2024,"Forecast","Actual") -> Forecast
...

Sheet Tables-BFSI
A1: KPI | B1: 2020 | C1: 2021 | D1: 2022 | E1: 2023 | F1: 2024 | H1: KPI | I1: 2025 | J1: 2026 | K1: 2027 | L1: 2028 | M1: 2029 | N1: 2030
A2: Loan Book | B2: ='[7]Balance Sheet-Banks'!G75 -> 1043670.8 | C2: ='[7]Balance Sheet-Banks'!H75 -> 1185283.5 | D2: ='[7]Balance Sheet-Banks'!I75 -> 1420942.3 | E2: ='[7]Balance Sheet-Banks'!J75 -> 1661949.3 | F2: ='[7]Balance Sheet-Banks'!K75 -> 2565891.4 | H2: Loan Book | I2: ='[7]Financial Projections'!M5 -> 3071660.5 | J2: ='[7]Financial Projections'!N5 -> 3677123 | K2: ='[7]Financial Projections'!O5 -> 4401929.7 | L2: ='[7]Financial Projections'!P5 -> 5269604.9 | M2: ='[7]Financial Projections'!Q5 -> 6308309.6 | N2: ='[7]Financial Projections'!R5 -> 7551755.9 | Q2: HDFC bank | R2: =(N3-I3)/I3 -> 0.98672201 | S2: =(N3/I3)^(1/6)-1 -> 0.1212166
A3: Deposits | B3: ='[7]Balance Sheet-Banks'!G13 -> 1146207.1 | C3: ='[7]Balance Sheet-Banks'!H13 -> 1333720.9 | D3: ='[7]Balance Sheet-Banks'!I13 -> 1558003 | E3: ='[7]Balance Sheet-Banks'!J13 -> 1882663.2 | F3: ='[7]Balance Sheet-Banks'!K13 -> 2376887.3 | H3: PAT | I3: ='[7]Financial Projections'!M14 -> 82628.654 | J3: ='[7]Financial Projections'!N14 -> 94913.599 | K3: ='[7]Financial Projections'!O14 -> 108199.59 | L3: ='[7]Financial Projections'!P14 -> 123663.11 | M3: ='[7]Financial Projections'!Q14 -> 141977.35 | N3: ='[7]Financial Projections'!R14 -> 164160.17 | Q3: ICICI Bank | R3: =(N9-I9)/I9 -> 1.287401 | S3: =(N9/I9)^(1/6)-1 -> 0.14786386
A4: NIM | B4: ='[7]Financial Ratios-Banks'!H5 -> 0.041907401 | C4: ='[7]Financial Ratios-Banks'!I5 -> 0.042672577 | D4: ='[7]Financial Ratios-Banks'!J5 -> 0.041360189 | E4: ='[7]Financial Ratios-Banks'!K5 -> 0.042775608 | F4: ='[7]Financial Ratios-Banks'!L5 -> 0.036261465 | H4: Revenue | I4: ='[7]Financial Projections'!M8 -> 322579.04 | J4: ='[7]Financial Projections'!N8 -> 412796.94 | K4: ='[7]Financial Projections'!O8 -> 531906.68 | L4: ='[7]Financial Projections'!P8 -> 689986.14 | M4: ='[7]Financial Projections'!Q8 -> 900791.13 | N4: ='[7]Financial Projections'!R8 -> 1183127 | Q4: SBI | R4: =(N15-I15)/I15 -> 0.34433338 | S4: =(N15/I15)^(1/6)-1 -> 0.050552668
A5: NPA | B5: ='[7]Financial Ratios-Banks'!H13 -> 0.004 | C5: ='[7]Financial Ratios-Banks'!I13 -> 0.0032 | D5: ='[7]Financial Ratios-Banks'!J13 -> 0.0027 | E5: ='[7]Financial Ratios-Banks'!K13 -> 0.0033 | F5: ='[7]Financial Ratios-Banks'!L13 -> 0.0043 | H5: PBT | I5: ='[7]Financial Projections'!M12 -> 110421.83 | J5: ='[7]Financial Projections'!N12 -> 126838.97 | K5: ='[7]Financial Projections'!O12 -> 144593.86 | L5: ='[7]Financial Projections'!P12 -> 165258.74 | M5: ='[7]Financial Projections'!Q12 -> 189733.2 | N5: ='[7]Financial Projections'!R12 -> 219377.48 | Q5: Axis | R5: =(N21-I21)/I21 -> 0.95399723 | S5: =(N21/I21)^(1/6)-1 -> 0.11811719
A6: ROA | B6: ='[7]Financial Ratios-Banks'!H6 -> 0.017972094 | C6: ='[7]Financial Ratios-Banks'!I6 -> 0.018238548 | D6: ='[7]Financial Ratios-Banks'!J6 -> 0.016239044 | E6: ='[7]Financial Ratios-Banks'!K6 -> 0.00815039 | F6: ='[7]Financial Ratios-Banks'!L6 -> 0.013160156 | Q6: Muthoot | R6: =(N27-I27)/I27 -> 0.88887761 | S6: =(N27/I27)^(1/6)-1 -> 0.11181869
A7: ROE | B7: ='[7]Financial Ratios-Banks'!H7 -> 0.15427255 | C7: ='[7]Financial Ratios-Banks'!I7 -> 0.1513796 | D7: ='[7]Financial Ratios-Banks'!J7 -> 0.15380539 | E7: ='[7]Financial Ratios-Banks'!K7 -> 0.15897022 | F7: ='[7]Financial Ratios-Banks'!L7 -> 0.13931348 | H7: KPI | I7: 2025 | J7: 2026 | K7: 2027 | L7: 2028 | M7: 2029 | N7: 2030 | Q7: Bajaj Finance | R7: =(N33-I33)/I33 -> 1.2408536 | S7: =(N33/I33)^(1/6)-1 -> 0.14393737
A8: CAR | B8: ='[7]Financial Ratios-Banks'!H16 -> 0.18523669 | C8: ='[7]Financial Ratios-Banks'!I16 -> 0.18790386 | D8: ='[7]Financial Ratios-Banks'!J16 -> 0.1889416 | E8: ='[7]Financial Ratios-Banks'!K16 -> 0.19258674 | F8: ='[7]Financial Ratios-Banks'!L16 -> 0.18800549 | H8: Loan Book | I8: ='[7]Financial Projections'!V5 -> 1415710.3 | J8: ='[7]Financial Projections'!W5 -> 1589683.9 | K8: ='[7]Financial Projections'!X5 -> 1785036.7 | L8: ='[7]Financial Projections'!Y5 -> 2004396.1 | M8: ='[7]Financial Projections'!Z5 -> 2250712 | N8: ='[7]Financial Projections'!AA5 -> 2527297.2 | Q8: BHFL | R8: =(N39-I39)/I39 -> 1.6061922 | S8: =(N39/I39)^(1/6)-1 -> 0.1730983
H9: PAT | I9: ='[7]Financial Projections'!V14 -> 52473.033 | J9: ='[7]Financial Projections'!W14 -> 63887.542 | K9: ='[7]Financial Projections'!X14 -> 74552.191 | L9: ='[7]Financial Projections'!Y14 -> 87219.296 | M9: ='[7]Financial Projections'!Z14 -> 102240.55 | N9: ='[7]Financial Projections'!AA14 -> 120026.87 | R9: =AVERAGE(R2:R8) -> 1.0440538 | S9: =AVERAGE(S2:S8) -> 0.12380067
A10: KPI | B10: 2020 | C10: 2021 | D10: 2022 | E10: 2023 | F10: 2024 | H10: Revenue | I10: ='[7]Financial Projections'!V8 -> 178387.83 | J10: ='[7]Financial Projections'!W8 -> 197195.77 | K10: ='[7]Financial Projections'!X8 -> 218724.97 | L10: ='[7]Financial Projections'!Y8 -> 243407.19 | M10: ='[7]Financial Projections'!Z8 -> 271744.09 | N10: ='[7]Financial Projections'!AA8 -> 304318.63
A11: Loan Book | B11: ='[7]Balance Sheet-Banks'!L75 -> 706246.09 | C11: ='[7]Balance Sheet-Banks'!M75 -> 733729.04 | D11: ='[7]Balance Sheet-Banks'!N75 -> 859020.4 | E11: ='[7]Balance Sheet-Banks'!O75 -> 1083866.3 | F11: ='[7]Balance Sheet-Banks'!P75 -> 1260776.2 | H11: PBT | I11: ='[7]Financial Projections'!V12 -> 70122.989 | J11: ='[7]Financial Projections'!W12 -> 85376.91 | K11: ='[7]Financial Projections'!X12 -> 99628.746 | L11: ='[7]Financial Projections'!Y12 -> 116556.59 | M11: ='[7]Financial Projections'!Z12 -> 136630.43 | N11: ='[7]Financial Projections'!AA12 -> 160399.39
A12: Deposits | B12: ='[7]Balance Sheet-Banks'!L13 -> 800784.45 | C12: ='[7]Balance Sheet-Banks'!M13 -> 932522.15 | D12: ='[7]Balance Sheet-Banks'!N13 -> 1064571.6 | E12: ='[7]Balance Sheet-Banks'!O13 -> 1210832.1 | F12: ='[7]Balance Sheet-Banks'!P13 -> 1443579.9
A13: NIM | B13: ='[7]Financial Ratios-Banks'!N5 -> 0.0349392 | C13: ='[7]Financial Ratios-Banks'!O5 -> 0.038412647 | D13: ='[7]Financial Ratios-Banks'!P5 -> 0.04059494 | E13: ='[7]Financial Ratios-Banks'!Q5 -> 0.040920667 | F13: ='[7]Financial Ratios-Banks'!R5 -> 0.040905303 | H13: KPI | I13: 2025 | J13: 2026 | K13: 2027 | L13: 2028 | M13: 2029 | N13: 2030
A14: NPA | B14: ='[7]Financial Ratios-Banks'!N13 -> 0.0114 | C14: ='[7]Financial Ratios-Banks'!O13 -> 0.0076 | D14: ='[7]Financial Ratios-Banks'!P13 -> 0.0048 | E14: ='[7]Financial Ratios-Banks'!Q13 -> 0.0042 | F14: ='[7]Financial Ratios-Banks'!R13 -> 0.0039 | H14: Loan Book | I14: ='[7]Financial Projections'!AE5 -> 4154046.7 | J14: ='[7]Financial Projections'!AF5 -> 4559952.7 | K14: ='[7]Financial Projections'!AG5 -> 5005521.1 | L14: ='[7]Financial Projections'!AH5 -> 5494627.5 | M14: ='[7]Financial Projections'!AI5 -> 6031526.1 | N14: ='[7]Financial Projections'!AJ5 -> 6620886.9
A15: ROA | B15: ='[7]Financial Ratios-Banks'!N6 -> 0.016537611 | C15: ='[7]Financial Ratios-Banks'!O6 -> 0.017596731 | D15: ='[7]Financial Ratios-Banks'!P6 -> 0.01903788 | E15: ='[7]Financial Ratios-Banks'!Q6 -> 0.0043304005 | F15: ='[7]Financial Ratios-Banks'!R6 -> 0.0050106544 | H15: PAT | I15: ='[7]Financial Projections'!AE14 -> 65752.222 | J15: ='[7]Financial Projections'!AF14 -> 78715.149 | K15: ='[7]Financial Projections'!AG14 -> 81703.994 | L15: ='[7]Financial Projections'!AH14 -> 84386.945 | M15: ='[7]Financial Projections'!AI14 -> 86658.405 | N15: ='[7]Financial Projections'!AJ14 -> 88392.907
A16: ROE | B16: ='[7]Financial Ratios-Banks'!N7 -> 0.086512931 | C16: ='[7]Financial Ratios-Banks'!O7 -> 0.10977408 | D16: ='[7]Financial Ratios-Banks'!P7 -> 0.13687891 | E16: ='[7]Financial Ratios-Banks'!Q7 -> 0.15581121 | F16: ='[7]Financial Ratios-Banks'!R7 -> 0.16667176 | H16: Revenue | I16: ='[7]Financial Projections'!AE8 -> 368705.01 | J16: ='[7]Financial Projections'!AF8 -> 406003.48 | K16: ='[7]Financial Projections'!AG8 -> 447082.82 | L16: ='[7]Financial Projections'!AH8 -> 492327.07 | M16: ='[7]Financial Projections'!AI8 -> 542159.37 | N16: ='[7]Financial Projections'!AJ8 -> 597045.88
A17: CAR | B17: ='[7]Financial Ratios-Banks'!N16 -> 0 | C17: ='[7]Financial Ratios-Banks'!O16 -> 0.1912 | D17: ='[7]Financial Ratios-Banks'!P16 -> 0.1916 | E17: ='[7]Financial Ratios-Banks'!Q16 -> 0 | F17: ='[7]Financial Ratios-Banks'!R16 -> 0 | H17: PBT | I17: ='[7]Financial Projections'!AE12 -> 87669.63 | J17: ='[7]Financial Projections'!AF12 -> 104953.53 | K17: ='[7]Financial Projections'!AG12 -> 108938.66 | L17: ='[7]Financial Projections'!AH12 -> 112515.93 | M17: ='[7]Financial Projections'!AI12 -> 115544.54 | N17: ='[7]Financial Projections'!AJ12 -> 117857.21
A19: KPI | B19: 2020 | C19: 2021 | D19: 2022 | E19: 2023 | F19: 2024 | H19: KPI | I19: 2025 | J19: 2026 | K19: 2027 | L19: 2028 | M19: 2029 | N19: 2030
A20: Loan Book | B20: ='[7]Balance Sheet-Banks'!Q75 -> 2374311.2 | C20: ='[7]Balance Sheet-Banks'!R75 -> 2500599 | D20: ='[7]Balance Sheet-Banks'!S75 -> 2794076 | E20: ='[7]Balance Sheet-Banks'!T75 -> 3267902.1 | F20: ='[7]Balance Sheet-Banks'!U75 -> 3784272.7 | H20: Loan Book | I20: ='[7]Financial Projections'!D5 -> 1113076.3 | J20: ='[7]Financial Projections'!E5 -> 1239765.3 | K20: ='[7]Financial Projections'!F5 -> 1380873.8 | L20: ='[7]Financial Projections'!G5 -> 1538043.1 | M20: ='[7]Financial Projections'!H5 -> 1713101.2 | N20: ='[7]Financial Projections'!I5 -> 1908084.2
A21: Deposits | B21: ='[7]Balance Sheet-Banks'!Q13 -> 3274160.6 | C21: ='[7]Balance Sheet-Banks'!R13 -> 3715331.2 | D21: ='[7]Balance Sheet-Banks'!S13 -> 4087410.6 | E21: ='[7]Balance Sheet-Banks'!T13 -> 4468535.5 | F21: ='[7]Balance Sheet-Banks'!U13 -> 4966537.5 | H21: PAT | I21: ='[7]Financial Projections'!D14 -> 26450.45 | J21: ='[7]Financial Projections'!E14 -> 34713.369 | K21: ='[7]Financial Projections'!F14 -> 38340.122 | L21: ='[7]Financial Projections'!G14 -> 42350.052 | M21: ='[7]Financial Projections'!H14 -> 46783.318 | N21: ='[7]Financial Projections'!I14 -> 51684.106
A22: NIM | B22: ='[7]Financial Ratios-Banks'!T5 -> 0.030180423 | C22: ='[7]Financial Ratios-Banks'!U5 -> 0.029813056 | D22: ='[7]Financial Ratios-Banks'!V5 -> 0.029269536 | E22: ='[7]Financial Ratios-Banks'!W5 -> 0.031048727 | F22: ='[7]Financial Ratios-Banks'!X5 -> 0.030442395 | H22: Revenue | I22: ='[7]Financial Projections'!D8 -> 86510.21 | J22: ='[7]Financial Projections'!E8 -> 97760.527 | K22: ='[7]Financial Projections'!F8 -> 110536.24 | L22: ='[7]Financial Projections'!G8 -> 125050.62 | M22: ='[7]Financial Projections'!H8 -> 141547.42 | N22: ='[7]Financial Projections'!I8 -> 160305.23
A23: NPA | B23: ='[7]Financial Ratios-Banks'!T13 -> 0.015 | C23: ='[7]Financial Ratios-Banks'!U13 -> 0.0102 | D23: ='[7]Financial Ratios-Banks'!V13 -> 0.0067 | E23: ='[7]Financial Ratios-Banks'!W13 -> 0.0057 | F23: ='[7]Financial Ratios-Banks'!X13 -> 0.0047 | H23: PBT | I23: ='[7]Financial Projections'!D12 -> 35347.388 | J23: ='[7]Financial Projections'!E12 -> 46389.642 | K23: ='[7]Financial Projections'!F12 -> 51236.299 | L23: ='[7]Financial Projections'!G12 -> 56595.018 | M23: ='[7]Financial Projections'!H12 -> 62519.468 | N23: ='[7]Financial Projections'!I12 -> 69068.697
A24: ROA | B24: ='[7]Financial Ratios-Banks'!T6 -> 0.0067817501 | C24: ='[7]Financial Ratios-Banks'!U6 -> 0.0094985652 | D24: ='[7]Financial Ratios-Banks'!V6 -> 0.010118874 | E24: ='[7]Financial Ratios-Banks'!W6 -> 0.0094985652 | F24: ='[7]Financial Ratios-Banks'!X6 -> 0.010118874
A25: ROE | B25: ='[7]Financial Ratios-Banks'!T7 -> 0.070179713 | C25: ='[7]Financial Ratios-Banks'!U7 -> 0.085135999 | D25: ='[7]Financial Ratios-Banks'!V7 -> 0.11476229 | E25: ='[7]Financial Ratios-Banks'!W7 -> 0.1521337 | F25: ='[7]Financial Ratios-Banks'!X7 -> 0.15825603 | H25: KPI | I25: 2025 | J25: 2026 | K25: 2027 | L25: 2028 | M25: 2029 | N25: 2030
A26: CAR | B26: ='[7]Financial Ratios-Banks'!T16 -> 0 | C26: ='[7]Financial Ratios-Banks'!U16 -> 0 | D26: ='[7]Financial Ratios-Banks'!V16 -> 0 | E26: ='[7]Financial Ratios-Banks'!W16 -> 0 | F26: ='[7]Financial Ratios-Banks'!X16 -> 0 | H26: Loan Book | I26: ='[7]Financial Projections'!BF5 -> 999866.05 | J26: ='[7]Financial Projections'!BG5 -> 1133648 | K26: ='[7]Financial Projections'!BH5 -> 1285330 | L26: ='[7]Financial Projections'!BI5 -> 1457307 | M26: ='[7]Financial Projections'!BJ5 -> 1652294.5 | N26: ='[7]Financial Projections'!BK5 -> 1873371.4
H27: PAT | I27: ='[7]Financial Projections'!BF14 -> 70110.225 | J27: ='[7]Financial Projections'!BG14 -> 79613.828 | K27: ='[7]Financial Projections'!BH14 -> 90409.088 | L27: ='[7]Financial Projections'!BI14 -> 102672.11 | M27: ='[7]Financial Projections'!BJ14 -> 116603.08 | N27: ='[7]Financial Projections'!BK14 -> 132429.63
A28: KPI | B28: 2020 | C28: 2021 | D28: 2022 | E28: 2023 | F28: 2024 | H28: Revenue | I28: ='[7]Financial Projections'!BF8 -> 121936.1 | J28: ='[7]Financial Projections'!BG8 -> 138463.52 | K28: ='[7]Financial Projections'!BH8 -> 157237.01 | L28: ='[7]Financial Projections'!BI8 -> 178562.77 | M28: ='[7]Financial Projections'!BJ8 -> 202788.87 | N28: ='[7]Financial Projections'!BK8 -> 230311.06
A29: Loan Book | B29: ='[7]Balance Sheet-Banks'!B75 -> 582958.8 | C29: ='[7]Balance Sheet-Banks'!C75 -> 625749.9 | D29: ='[7]Balance Sheet-Banks'!D75 -> 725125.5 | E29: ='[7]Balance Sheet-Banks'!E75 -> 868387.54 | F29: ='[7]Balance Sheet-Banks'!F75 -> 999333.48 | H29: PBT | I29: ='[7]Financial Projections'!BF12 -> 93692.669 | J29: ='[7]Financial Projections'!BG12 -> 106392.93 | K29: ='[7]Financial Projections'!BH12 -> 120819.31 | L29: ='[7]Financial Projections'!BI12 -> 137207.14 | M29: ='[7]Financial Projections'!BJ12 -> 155823.98 | N29: ='[7]Financial Projections'!BK12 -> 176973.99
A30: Deposits | B30: ='[7]Balance Sheet-Banks'!B13 -> 642157.2 | C30: ='[7]Balance Sheet-Banks'!C13 -> 698302.63 | D30: ='[7]Balance Sheet-Banks'!D13 -> 820914.16 | E30: ='[7]Balance Sheet-Banks'!E13 -> 945824.72 | F30: ='[7]Balance Sheet-Banks'!F13 -> 1067102.4
A31: NIM | B31: ='[7]Financial Ratios-Banks'!B5 -> 0.034839247 | C31: ='[7]Financial Ratios-Banks'!C5 -> 0.034978829 | D31: ='[7]Financial Ratios-Banks'!D5 -> 0.033932439 | E31: ='[7]Financial Ratios-Banks'!E5 -> 0.038097615 | F31: ='[7]Financial Ratios-Banks'!F5 -> 0.038573855 | H31: KPI | I31: 2025 | J31: 2026 | K31: 2027 | L31: 2028 | M31: 2029 | N31: 2030
A32: NPA | B32: ='[7]Financial Ratios-Banks'!B13 -> 0.0156 | C32: ='[7]Financial Ratios-Banks'!C13 -> 0.0105 | D32: ='[7]Financial Ratios-Banks'!D13 -> 0.0073 | E32: ='[7]Financial Ratios-Banks'!E13 -> 0.0039 | F32: ='[7]Financial Ratios-Banks'!F13 -> 0.0031 | H32: Loan Book | I32: ='[7]Financial Projections'!AW5 -> 385704.45 | J32: ='[7]Financial Projections'!AX5 -> 455933.1 | K32: ='[7]Financial Projections'!AY5 -> 538948.9 | L32: ='[7]Financial Projections'!AZ5 -> 637080.12 | M32: ='[7]Financial Projections'!BA5 -> 753078.97 | N32: ='[7]Financial Projections'!BB5 -> 890198.77
A33: ROA | B33: ='[7]Financial Ratios-Banks'!B6 -> 0.011847773 | C33: ='[7]Financial Ratios-Banks'!C6 -> 0.0080723855 | D33: ='[7]Financial Ratios-Banks'!D6 -> 0.017404077 | E33: ='[7]Financial Ratios-Banks'!E6 -> 0.017267152 | F33: ='[7]Financial Ratios-Banks'!F6 -> 0.017703058 | H33: PAT | I33: ='[7]Financial Projections'!AW14 -> 19512.441 | J33: ='[7]Financial Projections'!AX14 -> 22922.014 | K33: ='[7]Financial Projections'!AY14 -> 26931.852 | L33: ='[7]Financial Projections'!AZ14 -> 31648.302 | M33: ='[7]Financial Projections'!BA14 -> 37196.653 | N33: ='[7]Financial Projections'!BB14 -> 43724.524
A34: ROE | B34: ='[7]Financial Ratios-Banks'!B7 -> 0.021731233 | C34: ='[7]Financial Ratios-Banks'!C7 -> 0.069890799 | D34: ='[7]Financial Ratios-Banks'!D7 -> 0.11950818 | E34: ='[7]Financial Ratios-Banks'!E7 -> 0.083369707 | F34: ='[7]Financial Ratios-Banks'!F7 -> 0.16774405 | H34: Revenue | I34: ='[7]Financial Projections'!AW8 -> 40392.276 | J34: ='[7]Financial Projections'!AX8 -> 47451.994 | K34: ='[7]Financial Projections'!AY8 -> 55754.839 | L34: ='[7]Financial Projections'!AZ8 -> 65521.09 | M34: ='[7]Financial Projections'!BA8 -> 77010.265 | N34: ='[7]Financial Projections'!BB8 -> 90528.139
A35: CAR | B35: ='[7]Financial Ratios-Banks'!B16 -> 0.17526661 | C35: ='[7]Financial Ratios-Banks'!C16 -> 0.19119999 | D35: ='[7]Financial Ratios-Banks'!D16 -> 0.18539112 | E35: ='[7]Financial Ratios-Banks'!E16 -> 0.1763865 | F35: ='[7]Financial Ratios-Banks'!F16 -> 0.16632526 | H35: PBT | I35: ='[7]Financial Projections'!AW12 -> 26075.694 | J35: ='[7]Financial Projections'!AX12 -> 30632.119 | K35: ='[7]Financial Projections'!AY12 -> 35990.715 | L35: ='[7]Financial Projections'!AZ12 -> 42293.601 | M35: ='[7]Financial Projections'!BA12 -> 49708.21 | N35: ='[7]Financial Projections'!BB12 -> 58431.811
A37: KPI | B37: 2020 | C37: 2021 | D37: 2022 | E37: 2023 | F37: 2024 | H37: KPI | I37: 20252 | J37: 2026 | K37: 2027 | L37: 2028 | M37: 2029 | N37: 2030
A38: Loan Book | B38: ='[7]Balance Sheet-NBFCs'!L27 -> 470677.41 | C38: ='[7]Balance Sheet-NBFCs'!M27 -> 588085.17 | D38: ='[7]Balance Sheet-NBFCs'!N27 -> 645276.41 | E38: ='[7]Balance Sheet-NBFCs'!O27 -> 705543.84 | F38: ='[7]Balance Sheet-NBFCs'!P27 -> 881871.71 | H38: Loan Book | I38: ='[7]Financial Projections'!AN5 -> 97673.66 | J38: ='[7]Financial Projections'!AO5 -> 120303.32 | K38: ='[7]Financial Projections'!AP5 -> 148175.98 | L38: ='[7]Financial Projections'!AQ5 -> 182506.34 | M38: ='[7]Financial Projections'!AR5 -> 224790.59 | N38: ='[7]Financial Projections'!AS5 -> 276871.53
A39: Deposits | B39: ='[7]Balance Sheet-NBFCs'!L14 -> 2560.06 | C39: ='[7]Balance Sheet-NBFCs'!M14 -> 2579.53 | D39: ='[7]Balance Sheet-NBFCs'!N14 -> 2235.26 | E39: ='[7]Balance Sheet-NBFCs'!O14 -> 3314.76 | F39: ='[7]Balance Sheet-NBFCs'!P14 -> 4018.26 | H39: PAT | I39: ='[7]Financial Projections'!AN14 -> 1973.3077 | J39: ='[7]Financial Projections'!AO14 -> 2376.9939 | K39: ='[7]Financial Projections'!AP14 -> 2872.1259 | L39: ='[7]Financial Projections'!AQ14 -> 3479.8093 | M39: ='[7]Financial Projections'!AR14 -> 4226.0367 | N39: ='[7]Financial Projections'!AS14 -> 5142.8191
A40: NIM | B40: ='[7]Financial Ratios-NBFCs'!L5 -> 0.13088292 | C40: ='[7]Financial Ratios-NBFCs'!M5 -> 0.11923922 | D40: ='[7]Financial Ratios-NBFCs'!N5 -> 0.1178799 | E40: ='[7]Financial Ratios-NBFCs'!O5 -> 0.10332415 | F40: ='[7]Financial Ratios-NBFCs'!P5 -> 0.10253835 | H40: Revenue | I40: ='[7]Financial Projections'!AN8 -> 3130.5905 | J40: ='[7]Financial Projections'!AO8 -> 3772.7275 | K40: ='[7]Financial Projections'!AP8 -> 4560.4009 | L40: ='[7]Financial Projections'!AQ8 -> 5527.2035 | M40: ='[7]Financial Projections'!AR8 -> 6714.5059 | N40: ='[7]Financial Projections'!AS8 -> 8173.2592
A41: NPA | B41: ='[7]Financial Ratios-NBFCs'!L13 -> 0.0196 | C41: ='[7]Financial Ratios-NBFCs'!M13 -> 0.0078 | D41: ='[7]Financial Ratios-NBFCs'!N13 -> 0.0271 | E41: ='[7]Financial Ratios-NBFCs'!O13 -> 0.0345 | F41: ='[7]Financial Ratios-NBFCs'!P13 -> 0.0293 | H41: PBT | I41: ='[7]Financial Projections'!AN12 -> 2637.0543 | J41: ='[7]Financial Projections'!AO12 -> 3176.5253 | K41: ='[7]Financial Projections'!AP12 -> 3838.2011 | L41: ='[7]Financial Projections'!AQ12 -> 4650.2864 | M41: ='[7]Financial Projections'!AR12 -> 5647.5166 | N41: ='[7]Financial Projections'!AS12 -> 6872.6702
A42: ROA | B42: ='[7]Financial Ratios-NBFCs'!L6 -> 0.057736576 | C42: ='[7]Financial Ratios-NBFCs'!M6 -> 0.055635055 | D42: ='[7]Financial Ratios-NBFCs'!N6 -> 0.052823772 | E42: ='[7]Financial Ratios-NBFCs'!O6 -> 0.045786843 | F42: ='[7]Financial Ratios-NBFCs'!P6 -> 0.046310986
...

Sheet Tables-FMCG
A1: KPI | B1: 2020 | C1: 2021 | D1: 2022 | E1: 2023 | F1: 2024 | G1: 2025 | I1: KPI | J1: 2020 | K1: 2021 | L1: 2022 | M1: 2023 | N1: 2024 | O1: 2025 | Q1: KPI | R1: 2020 | S1: 2021 | T1: 2022 | U1: 2023 | V1: 2024 | W1: 2025
A2: Revenue | B2: ='[8]Income Statement'!B6 -> 24930.19 | C2: ='[8]Income Statement'!C6 -> 24339.27 | D2: ='[8]Income Statement'!D6 -> 31093.76 | E2: ='[8]Income Statement'!E6 -> 42968.9 | F2: ='[8]Income Statement'!F6 -> 50935.28 | G2: ='[8]Income Statement'!G6 -> 59482.36 | I2: Revenue | J2: ='[8]Income Statement'!Q6 -> 53991.36 | K2: ='[8]Income Statement'!R6 -> 55787.68 | L2: ='[8]Income Statement'!S6 -> 67041.31 | M2: ='[8]Income Statement'!T6 -> 78498.7 | N2: ='[8]Income Statement'!U6 -> 76584.65 | O2: ='[8]Income Statement'!V6 -> 84142.47 | Q2: Revenue | R2: ='[8]Income Statement'!AG6 -> 3635.4 | S2: ='[8]Income Statement'!AH6 -> 2794.56 | T2: ='[8]Income Statement'!AI6 -> 4673.23 | U2: ='[8]Income Statement'!AJ6 -> 8502.94 | V2: ='[8]Income Statement'!AK6 -> 12664.38 | W2: ='[8]Income Statement'!AL6 -> 17353.17
A3: EBITDA | B3: ='[8]Income Statement'!B15+'[8]Income Statement'!B11+'[8]Income Statement'!B12 -> 2188.3 | C3: ='[8]Income Statement'!C15+'[8]Income Statement'!C11+'[8]Income Statement'!C12 -> 1939.26 | D3: ='[8]Income Statement'!D15+'[8]Income Statement'!D11+'[8]Income Statement'!D12 -> 2615.99 | E3: ='[8]Income Statement'!E15+'[8]Income Statement'!E11+'[8]Income Statement'!E12 -> 3766.37 | F3: ='[8]Income Statement'!F15+'[8]Income Statement'!F11+'[8]Income Statement'!F12 -> 4250.22 | G3: ='[8]Income Statement'!G15+'[8]Income Statement'!G11+'[8]Income Statement'!G12 -> 4611.64 | I3: EBITDA | J3: ='[8]Income Statement'!Q18+'[8]Income Statement'!Q13+'[8]Income Statement'!Q14 -> 21866.27 | K3: ='[8]Income Statement'!R18+'[8]Income Statement'!R13+'[8]Income Statement'!R14 -> 19628.34 | L3: ='[8]Income Statement'!S18+'[8]Income Statement'!S13+'[8]Income Statement'!S14 -> 22512.24 | M3: ='[8]Income Statement'!T18+'[8]Income Statement'!T13+'[8]Income Statement'!T14 -> 27694.46 | N3: ='[8]Income Statement'!U18+'[8]Income Statement'!U13+'[8]Income Statement'!U14 -> 27957.44 | O3: ='[8]Income Statement'!V18+'[8]Income Statement'!V13+'[8]Income Statement'!V14 -> 28618.32 | Q3: EBITDA | R3: ='[8]Income Statement'!AG15+'[8]Income Statement'!$AG$11+'[8]Income Statement'!$AG$12 -> 688.46 | S3: ='[8]Income Statement'!AH15+'[8]Income Statement'!$AG$11+'[8]Income Statement'!$AG$12 -> 360.59 | T3: ='[8]Income Statement'!AI15+'[8]Income Statement'!$AG$11+'[8]Income Statement'!$AG$12 -> 626.56 | U3: ='[8]Income Statement'!AJ15+'[8]Income Statement'!$AG$11+'[8]Income Statement'!$AG$12 -> 964.7 | V3: ='[8]Income Statement'!AK15+'[8]Income Statement'!$AG$11+'[8]Income Statement'!$AG$12 -> 1714.23 | W3: ='[8]Income Statement'!AL15+'[8]Income Statement'!$AG$11+'[8]Income Statement'!$AG$12 -> 2436.28 | Z3: Dmart | AA3: =(F11-B11)/B11 -> 0.63910992 | AB3: =(F11/B11)^(1/5)-1 -> 0.10387937
A4: Net Profit | B4: ='[8]Income Statement'!$B$21 -> 1300.98 | C4: ='[8]Income Statement'!$B$21 -> 1300.98 | D4: ='[8]Income Statement'!$B$21 -> 1300.98 | E4: ='[8]Income Statement'!$B$21 -> 1300.98 | F4: ='[8]Income Statement'!$B$21 -> 1300.98 | G4: ='[8]Income Statement'!$B$21 -> 1300.98 | I4: Net Profit | J4: ='[8]Income Statement'!$Q$30 -> 15592.78 | K4: ='[8]Income Statement'!$Q$30 -> 15592.78 | L4: ='[8]Income Statement'!$Q$30 -> 15592.78 | M4: ='[8]Income Statement'!$Q$30 -> 15592.78 | N4: ='[8]Income Statement'!$Q$30 -> 15592.78 | O4: ='[8]Income Statement'!$Q$30 -> 15592.78 | Q4: Net Profit | R4: ='[8]Income Statement'!AG25 -> 105.98 | S4: ='[8]Income Statement'!AH25 -> -181.13 | T4: ='[8]Income Statement'!AI25 -> 34.6 | U4: ='[8]Income Statement'!AJ25 -> 393.69 | V4: ='[8]Income Statement'!AK25 -> 1477.39 | W4: ='[8]Income Statement'!AL25 -> 1534.41 | Z4: HUL | AA4: =(G25-B25)/B25 -> 0.14387076 | AB4: =(G25/B25)^(1/6)-1 -> 0.022655818
A5: EBITDA Margin | B5: =[8]!Table40[[#This Row],[2020]] -> 0.1360556 | C5: =[8]!Table40[[#This Row],[2021]] -> 0.1378773 | D5: =[8]!Table40[[#This Row],[2022]] -> 0.13379597 | E5: =[8]!Table40[[#This Row],[2023]] -> 0.13722527 | F5: =[8]!Table40[[#This Row],[2024]] -> 0.13530239 | G5: =[8]!Table40[[#This Row],[2025]] -> 0.13463532 | I5: EBITDA Margin | J5: =J3/J2 -> 0.40499573 | K5: =K3/K2 -> 0.35184005 | L5: =L3/L2 -> 0.33579654 | M5: =M3/M2 -> 0.35280151 | N5: =N3/N2 -> 0.36505279 | O5: =O3/O2 -> 0.34011742 | Q5: EBITDA Margin | R5: =R3/R2 -> 0.18937668 | S5: =S3/S2 -> 0.12903284 | T5: =T3/T2 -> 0.13407429 | U5: =U3/U2 -> 0.11345488 | V5: =V3/V2 -> 0.13535838 | W5: =W3/W2 -> 0.14039395 | Z5: ITC | AA5: =(V11-R11)/R11 -> 2.1604419 | AB5: =(V11/R11)^(1/5)-1 -> 0.25877921
A6: Net Profit Margin | B6: =[8]!Table40[[#This Row],[2020]] -> 0.052310798 | C6: =[8]!Table40[[#This Row],[2021]] -> 0.045538138 | D6: =[8]!Table40[[#This Row],[2022]] -> 0.048178816 | E6: =[8]!Table40[[#This Row],[2023]] -> 0.055517377 | F6: =[8]!Table40[[#This Row],[2024]] -> 0.04992456 | G6: =[8]!Table40[[#This Row],[2025]] -> 0.045612179 | I6: Net Profit Margin | J6: =J4/J2 -> 0.28880139 | K6: =K4/K2 -> 0.27950221 | L6: =L4/L2 -> 0.23258466 | M6: =M4/M2 -> 0.19863743 | N6: =N4/N2 -> 0.2036019 | O6: =O4/O2 -> 0.18531403 | Q6: Net Profit Margin | R6: =R4/R2 -> 0.029152225 | S6: =S4/S2 -> -0.064815212 | T6: =T4/T2 -> 0.0074038727 | U6: =U4/U2 -> 0.046300456 | V6: =V4/V2 -> 0.11665711 | W6: =W4/W2 -> 0.088422461 | Z6: Titan | AA6: =(N25-J25)/J25 -> 1.0528355 | AB6: =(N11/J11)^(1/5)-1 -> 0.0031827774
Z7: Trent | AA7: =(W25-R25)/R25 -> 0.97596433 | AB7: =(N25/J25)^(1/5)-1 -> 0.15470442
A8: Forecasts | B8: 2026 | C8: 2027 | D8: 2028 | E8: 2029 | F8: 2030 | I8: Forecasts | J8: 2026 | K8: 2027 | L8: 2028 | M8: 2029 | N8: 2030 | Q8: Forecasts | R8: 2026 | S8: 2027 | T8: 2028 | U8: 2029 | V8: 2030 | Z8: VBL | AA8: =(N11-J11)/J11 -> 0.016015511 | AB8: =(W25/R25)^(1/6)-1 -> 0.12020245
A9: Revenue | B9: ='[8]Income Statement Forecast'!D6 -> 68759.671 | C9: ='[8]Income Statement Forecast'!E6 -> 79484.029 | D9: ='[8]Income Statement Forecast'!F6 -> 91881.154 | E9: ='[8]Income Statement Forecast'!G6 -> 106211.97 | F9: ='[8]Income Statement Forecast'!H6 -> 122778.12 | I9: Revenue | J9: ='[8]Income Statement Forecast'!W6 -> 90670.71 | K9: ='[8]Income Statement Forecast'!X6 -> 97722.988 | L9: ='[8]Income Statement Forecast'!Y6 -> 105341.29 | M9: ='[8]Income Statement Forecast'!Z6 -> 113570.96 | N9: ='[8]Income Statement Forecast'!AA6 -> 122461 | Q9: Revenue | R9: ='[8]Income Statement Forecast'!AO6 -> 22575.396 | S9: ='[8]Income Statement Forecast'!AP6 -> 29381.465 | T9: ='[8]Income Statement Forecast'!AQ6 -> 38252.548 | U9: ='[8]Income Statement Forecast'!AR6 -> 49816.053 | V9: ='[8]Income Statement Forecast'!AS6 -> 64890.066 | AA9: =AVERAGE(AA3:AA8) -> 0.83137299 | AB9: =AVERAGE(AB3:AB8) -> 0.11056734
A10: EBITDA | B10: ='[8]Income Statement Forecast'!D12 -> 4698.078 | C10: ='[8]Income Statement Forecast'!E12 -> 5412.4404 | D10: ='[8]Income Statement Forecast'!F12 -> 6235.1236 | E10: ='[8]Income Statement Forecast'!G12 -> 7182.4997 | F10: ='[8]Income Statement Forecast'!H12 -> 8273.4063 | I10: EBITDA | J10: ='[8]Income Statement Forecast'!W12 -> 32462.98 | K10: ='[8]Income Statement Forecast'!X12 -> 34987.918 | L10: ='[8]Income Statement Forecast'!Y12 -> 37715.511 | M10: ='[8]Income Statement Forecast'!Z12 -> 40661.995 | N10: ='[8]Income Statement Forecast'!AA12 -> 43844.908 | Q10: EBITDA | R10: ='[8]Income Statement Forecast'!AO12 -> 3711.5639 | S10: ='[8]Income Statement Forecast'!AP12 -> 4830.5324 | T10: ='[8]Income Statement Forecast'!AQ12 -> 6289.0048 | U10: ='[8]Income Statement Forecast'!AR12 -> 8190.1315 | V10: ='[8]Income Statement Forecast'!AS12 -> 10668.412
A11: Net Profit | B11: ='[8]Income Statement Forecast'!D18 -> 2632.8514 | C11: ='[8]Income Statement Forecast'!E18 -> 2965.0562 | D11: ='[8]Income Statement Forecast'!F18 -> 3350.9217 | E11: ='[8]Income Statement Forecast'!G18 -> 3798.1351 | F11: ='[8]Income Statement Forecast'!H18 -> 4315.5329 | I11: Net Profit | J11: ='[8]Income Statement Forecast'!W18 -> 30948.524 | K11: ='[8]Income Statement Forecast'!X18 -> 25159.063 | L11: ='[8]Income Statement Forecast'!Y18 -> 27092.187 | M11: ='[8]Income Statement Forecast'!Z18 -> 29183.086 | N11: ='[8]Income Statement Forecast'!AA18 -> 31444.181 | Q11: Net Profit | R11: ='[8]Income Statement Forecast'!AO18 -> 1477.9384 | S11: ='[8]Income Statement Forecast'!AP18 -> 2039.1123 | T11: ='[8]Income Statement Forecast'!AQ18 -> 2716.9239 | U11: ='[8]Income Statement Forecast'!AR18 -> 3571.8102 | V11: ='[8]Income Statement Forecast'!AS18 -> 4670.9384
A12: EBITDA Margin | B12: =B10/B9 -> 0.068326069 | C12: =C10/C9 -> 0.068094691 | D12: =D10/D9 -> 0.067860745 | E12: =E10/E9 -> 0.0676242 | F12: =F10/F9 -> 0.067385023 | I12: EBITDA Margin | J12: =J10/J9 -> 0.35803161 | K12: =K10/K9 -> 0.35803161 | L12: =L10/L9 -> 0.35803161 | M12: =M10/M9 -> 0.35803161 | N12: =N10/N9 -> 0.35803161 | Q12: EBITDA Margin | R12: =R10/R9 -> 0.16440747 | S12: =S10/S9 -> 0.16440747 | T12: =T10/T9 -> 0.16440747 | U12: =U10/U9 -> 0.16440747 | V12: =V10/V9 -> 0.16440747
A13: Net Profit Margin | B13: =B11/B9 -> 0.038290634 | C13: =C11/C9 -> 0.037303798 | D13: =D11/D9 -> 0.036470174 | E13: =E11/E9 -> 0.035759952 | F13: =F11/F9 -> 0.035149039 | I13: Net Profit Margin | J13: =J11/J9 -> 0.3413288 | K13: =K11/K9 -> 0.25745286 | L13: =L11/L9 -> 0.25718488 | M13: =M11/M9 -> 0.25695904 | N13: =N11/N9 -> 0.25676894 | Q13: Net Profit Margin | R13: =R11/R9 -> 0.065466775 | S13: =S11/S9 -> 0.069401316 | T13: =T11/T9 -> 0.071025959 | U13: =U11/U9 -> 0.071699984 | V13: =V11/V9 -> 0.071982335
A15: KPI | B15: 2020 | C15: 2021 | D15: 2022 | E15: 2023 | F15: 2024 | I15: KPI | J15: 2020 | K15: 2021 | L15: 2022 | M15: 2023 | N15: 2024 | O15: 2025 | Q15: KPI | R15: 2020 | S15: 2021 | T15: 2022 | U15: 2023 | V15: 2024
A16: Revenue | B16: ='[8]Income Statement'!J6 -> 40415 | C16: ='[8]Income Statement'!K6 -> 47438 | D16: ='[8]Income Statement'!L6 -> 52704 | E16: ='[8]Income Statement'!M6 -> 61092 | F16: ='[8]Income Statement'!N6 -> 62707 | I16: Revenue | J16: ='[8]Income Statement'!Y6 -> 21205 | K16: ='[8]Income Statement'!Z6 -> 21830 | L16: ='[8]Income Statement'!AA6 -> 29033 | M16: ='[8]Income Statement'!AB6 -> 40883 | N16: ='[8]Income Statement'!AC6 -> 51617 | O16: ='[8]Income Statement'!AD6 -> 60942 | Q16: Revenue | R16: ='[8]Income Statement'!AO6 -> 6592.76 | S16: ='[8]Income Statement'!AP6 -> 9026.216 | T16: ='[8]Income Statement'!AQ6 -> 13429.407 | U16: ='[8]Income Statement'!AR6 -> 16400.422 | V16: ='[8]Income Statement'!AS6 -> 20602.596
A17: EBITDA | B17: ='[8]Income Statement'!J16+'[8]Income Statement'!J12+'[8]Income Statement'!J13 -> 10493 | C17: ='[8]Income Statement'!K16+'[8]Income Statement'!K12+'[8]Income Statement'!K13 -> 12036 | D17: ='[8]Income Statement'!L16+'[8]Income Statement'!L12+'[8]Income Statement'!L13 -> 13115 | E17: ='[8]Income Statement'!M16+'[8]Income Statement'!M12+'[8]Income Statement'!M13 -> 14660 | F17: ='[8]Income Statement'!N16+'[8]Income Statement'!N12+'[8]Income Statement'!N13 -> 15474 | I17: EBITDA | J17: ='[8]Income Statement'!Y16+'[8]Income Statement'!Y12+'[8]Income Statement'!Y13 -> 2620 | K17: ='[8]Income Statement'!Z16+'[8]Income Statement'!Z12+'[8]Income Statement'!Z13 -> 1910 | L17: ='[8]Income Statement'!AA16+'[8]Income Statement'!AA12+'[8]Income Statement'!AA13 -> 3575 | M17: ='[8]Income Statement'!AB16+'[8]Income Statement'!AB12+'[8]Income Statement'!AB13 -> 5187 | N17: ='[8]Income Statement'!AC16+'[8]Income Statement'!AC12+'[8]Income Statement'!AC13 -> 5825 | O17: ='[8]Income Statement'!AD16+'[8]Income Statement'!AD12+'[8]Income Statement'!AD13 -> 6180 | Q17: EBITDA | R17: =[8]!VBL_IS[[#This Row],[2020]]+'[8]Income Statement'!AO13+'[8]Income Statement'!AO14 -> 1238.837 | S17: =[8]!VBL_IS[[#This Row],[2021]]+'[8]Income Statement'!AP13+'[8]Income Statement'!AP14 -> 1722.57 | T17: =[8]!VBL_IS[[#This Row],[2022]]+'[8]Income Statement'!AQ13+'[8]Income Statement'!AQ14 -> 2826.954 | U17: =[8]!VBL_IS[[#This Row],[2023]]+'[8]Income Statement'!AR13+'[8]Income Statement'!AR14 -> 3688.844 | V17: =[8]!VBL_IS[[#This Row],[2024]]+'[8]Income Statement'!AS13+'[8]Income Statement'!AS14 -> 4832.339
A18: Net Profit | B18: ='[8]Income Statement'!$J$27 -> 6756 | C18: ='[8]Income Statement'!$J$27 -> 6756 | D18: ='[8]Income Statement'!$J$27 -> 6756 | E18: ='[8]Income Statement'!$J$27 -> 6756 | F18: ='[8]Income Statement'!$J$27 -> 6756 | I18: Net Profit | J18: ='[8]Income Statement'!Y28 -> 1493 | K18: ='[8]Income Statement'!Z28 -> 974 | L18: ='[8]Income Statement'!AA28 -> 2198 | M18: ='[8]Income Statement'!AB28 -> 3274 | N18: ='[8]Income Statement'!AC28 -> 3496 | O18: ='[8]Income Statement'!AD28 -> 3337 | Q18: Net Profit | R18: ='[8]Income Statement'!AO27 -> 357.268 | S18: ='[8]Income Statement'!AP27 -> 746.052 | T18: ='[8]Income Statement'!AQ27 -> 1550.114 | U18: ='[8]Income Statement'!AR27 -> 2101.813 | V18: ='[8]Income Statement'!AS27 -> 2634.284
A19: EBITDA Margin | B19: =B17/B16 -> 0.25963133 | C19: =C17/C16 -> 0.25372065 | D19: =D17/D16 -> 0.24884259 | E19: =E17/E16 -> 0.23996595 | F19: =F17/F16 -> 0.24676671 | I19: EBITDA Margin | J19: =J17/J16 -> 0.12355577 | K19: =K17/K16 -> 0.087494274 | L19: =L17/L16 -> 0.12313574 | M19: =M17/M16 -> 0.12687425 | N19: =N17/N16 -> 0.11285042 | O19: =O17/O16 -> 0.1014079 | Q19: EBITDA Margin | R19: =R17/R16 -> 0.18790871 | S19: =S17/S16 -> 0.19084077 | T19: =T17/T16 -> 0.21050475 | U19: =U17/U16 -> 0.22492372 | V19: =V17/V16 -> 0.23455001
A20: Net Profit Margin | B20: =B18/B16 -> 0.16716566 | C20: =C18/C16 -> 0.14241747 | D20: =D18/D16 -> 0.12818761 | E20: =E18/E16 -> 0.11058731 | F20: =F18/F16 -> 0.10773917 | I20: Net Profit Margin | J20: =J18/J16 -> 0.070407923 | K20: =K18/K16 -> 0.044617499 | L20: =L18/L16 -> 0.075706954 | M20: =M18/M16 -> 0.080082186 | N20: =N18/N16 -> 0.067729624 | O20: =O18/O16 -> 0.054756982 | Q20: Net Profit Margin | R20: =R18/R16 -> 0.054190961 | S20: =S18/S16 -> 0.082653905 | T20: =T18/T16 -> 0.11542684 | U20: =U18/U16 -> 0.12815603 | V20: =V18/V16 -> 0.12786175
A22: Forecasts | B22: 2025 | C22: 2026 | D22: 2027 | E22: 2028 | F22: 2029 | G22: 2030 | I22: Forecasts | J22: 2026 | K22: 2027 | L22: 2028 | M22: 2029 | N22: 2030 | Q22: Forecasts | R22: 2025 | S22: 2026 | T22: 2027 | U22: 2028 | V22: 2029 | W22: 2030
A23: Revenue | B23: ='[8]Income Statement Forecast'!M6 -> 67473.415 | C23: ='[8]Income Statement Forecast'!N6 -> 72603.056 | D23: ='[8]Income Statement Forecast'!O6 -> 78123.642 | E23: ='[8]Income Statement Forecast'!P6 -> 84065.008 | F23: ='[8]Income Statement Forecast'!Q6 -> 90459.271 | G23: ='[8]Income Statement Forecast'!R6 -> 97340.997 | I23: Revenue | J23: ='[8]Income Statement Forecast'!AF6 -> 72666.305 | K23: ='[8]Income Statement Forecast'!AG6 -> 86646.384 | L23: ='[8]Income Statement Forecast'!AH6 -> 103316.29 | M23: ='[8]Income Statement Forecast'!AI6 -> 123193.61 | N23: ='[8]Income Statement Forecast'!AJ6 -> 146895.54 | Q23: Revenue | R23: ='[8]Income Statement Forecast'!AX6 -> 24911.41 | S23: ='[8]Income Statement Forecast'!AY6 -> 30121.378 | T23: ='[8]Income Statement Forecast'!AZ6 -> 36420.972 | U23: ='[8]Income Statement Forecast'!BA6 -> 44038.083 | V23: ='[8]Income Statement Forecast'!BB6 -> 53248.263 | W23: ='[8]Income Statement Forecast'!BC6 -> 64384.698
A24: EBITDA | B24: ='[8]Income Statement Forecast'!M12 -> 16382.398 | C24: ='[8]Income Statement Forecast'!N12 -> 17741.328 | D24: ='[8]Income Statement Forecast'!O12 -> 19210.801 | E24: ='[8]Income Statement Forecast'!P12 -> 20799.659 | F24: ='[8]Income Statement Forecast'!Q12 -> 22517.439 | G24: ='[8]Income Statement Forecast'!R12 -> 24374.429 | I24: EBITDA | J24: ='[8]Income Statement Forecast'!AF12 -> 8178.8149 | K24: ='[8]Income Statement Forecast'!AG12 -> 9752.3155 | L24: ='[8]Income Statement Forecast'!AH12 -> 11628.565 | M24: ='[8]Income Statement Forecast'!AI12 -> 13865.818 | N24: ='[8]Income Statement Forecast'!AJ12 -> 16533.543 | Q24: EBITDA | R24: ='[8]Income Statement Forecast'!AX12 -> 5659.2597 | S24: ='[8]Income Statement Forecast'!AY12 -> 6842.8364 | T24: ='[8]Income Statement Forecast'!AZ12 -> 8273.9492 | U24: ='[8]Income Statement Forecast'!BA12 -> 10004.369 | V24: ='[8]Income Statement Forecast'!BB12 -> 12096.696 | W24: ='[8]Income Statement Forecast'!BC12 -> 14626.62
A25: Net Profit | B25: ='[8]Income Statement Forecast'!M18 -> 14602.833 | C25: ='[8]Income Statement Forecast'!N18 -> 11942.975 | D25: ='[8]Income Statement Forecast'!O18 -> 13021.884 | E25: ='[8]Income Statement Forecast'!P18 -> 14169.15 | F25: ='[8]Income Statement Forecast'!Q18 -> 15393.528 | G25: ='[8]Income Statement Forecast'!R18 -> 16703.753 | I25: Net Profit | J25: ='[8]Income Statement Forecast'!AF18 -> 5173.7368 | K25: ='[8]Income Statement Forecast'!AG18 -> 6215.2795 | L25: ='[8]Income Statement Forecast'!AH18 -> 7442.2486 | M25: ='[8]Income Statement Forecast'!AI18 -> 8895.1786 | N25: ='[8]Income Statement Forecast'!AJ18 -> 10620.831 | Q25: Net Profit | R25: ='[8]Income Statement Forecast'!AX18 -> 4306.8035 | S25: ='[8]Income Statement Forecast'!AY18 -> 4009.3708 | T25: ='[8]Income Statement Forecast'!AZ18 -> 4835.3868 | U25: ='[8]Income Statement Forecast'!BA18 -> 5835.4005 | V25: ='[8]Income Statement Forecast'!BB18 -> 7045.6798 | W25: ='[8]Income Statement Forecast'!BC18 -> 8510.09
A26: EBITDA Margin | B26: =B24/B23 -> 0.24279781 | C26: =C24/C23 -> 0.24436062 | D26: =D24/D23 -> 0.24590253 | E26: =E24/E23 -> 0.24742351 | F26: =F24/F23 -> 0.24892351 | G26: =G24/G23 -> 0.2504025 | I26: EBITDA Margin | J26: =J24/J23 -> 0.11255306 | K26: =K24/K23 -> 0.11255306 | L26: =L24/L23 -> 0.11255306 | M26: =M24/M23 -> 0.11255306 | N26: =N24/N23 -> 0.11255306 | Q26: EBITDA Margin | R26: =R24/R23 -> 0.22717541 | S26: =S24/S23 -> 0.22717541 | T26: =T24/T23 -> 0.22717541 | U26: =U24/U23 -> 0.22717541 | V26: =V24/V23 -> 0.22717541 | W26: =W24/W23 -> 0.22717541
A27: Net Profit Margin | B27: =B25/B23 -> 0.2164235 | C27: =C25/C23 -> 0.16449686 | D27: =D25/D23 -> 0.16668302 | E27: =E25/E23 -> 0.16854992 | F27: =F25/F23 -> 0.17017081 | G27: =G25/G23 -> 0.17160039 | I27: Net Profit Margin | J27: =J25/J23 -> 0.071198567 | K27: =K25/K23 -> 0.07173155 | L27: =L25/L23 -> 0.072033641 | M27: =M25/M23 -> 0.072204867 | N27: =N25/N23 -> 0.072301925 | Q27: Net Profit Margin | R27: =R25/R23 -> 0.17288477 | S27: =S25/S23 -> 0.13310715 | T27: =T25/T23 -> 0.1327638 | U27: =U25/U23 -> 0.13250805 | V27: =V25/V23 -> 0.13231755 | W27: =W25/W23 -> 0.13217566

Sheet Tables-Pharma
A1: KPI | B1: 2020 | C1: 2021 | D1: 2022 | E1: 2023 | F1: 2024 | G1: 2025 | I1: KPI | J1: 2020 | K1: 2021 | L1: 2022 | M1: 2023 | N1: 2024 | O1: 2025
A2: Revenue | B2: ='[9]Income Statement'!B7 -> 5584.05 | C2: ='[9]Income Statement'!C7 -> 7031.96 | D2: ='[9]Income Statement'!D7 -> 9073.7 | E2: ='[9]Income Statement'!E7 -> 8112.17 | F2: ='[9]Income Statement'!F7 -> 8184 | G2: ='[9]Income Statement'!G7 -> 9712 | I2: Revenue | J2: ='[9]Income Statement'!Z9 -> 18137.6 | K2: ='[9]Income Statement'!AA9 -> 19338.9 | L2: ='[9]Income Statement'!AB9 -> 22029.6 | M2: ='[9]Income Statement'!AC9 -> 25725.2 | N2: ='[9]Income Statement'!AD9 -> 28905.4 | O2: ='[9]Income Statement'!AE9 -> 33741.2 | R2: Divis | S2: =(F15-B15)/B15 -> 0.40998179 | T2: =(F15/B15)^(1/5)-1 -> 0.071131276
A3: EBITDA | B3: ='[9]Income Statement'!B17+'[9]Income Statement'!B13+'[9]Income Statement'!B14 -> 2011.8 | C3: ='[9]Income Statement'!C17+'[9]Income Statement'!C13+'[9]Income Statement'!C14 -> 2922.5 | D3: ='[9]Income Statement'!D17+'[9]Income Statement'!D13+'[9]Income Statement'!D14 -> 3995.81 | E3: ='[9]Income Statement'!E17+'[9]Income Statement'!E13+'[9]Income Statement'!E14 -> 2712.48 | F3: ='[9]Income Statement'!F17+'[9]Income Statement'!F13+'[9]Income Statement'!F14 -> 2544 | G3: ='[9]Income Statement'!G17+'[9]Income Statement'!G13+'[9]Income Statement'!G14 -> 3320 | I3: EBITDA | J3: ='[9]Income Statement'!Z20+'[9]Income Statement'!Z17+'[9]Income Statement'!Z15 -> 3091 | K3: ='[9]Income Statement'!AA20+'[9]Income Statement'!AA17+'[9]Income Statement'!AA15 -> 4161.3 | L3: ='[9]Income Statement'!AB20+'[9]Income Statement'!AB17+'[9]Income Statement'!AB15 -> 4252.1 | M3: ='[9]Income Statement'!AC20+'[9]Income Statement'!AC17+'[9]Income Statement'!AC15 -> 7404.5 | N3: ='[9]Income Statement'!AD20+'[9]Income Statement'!AD17+'[9]Income Statement'!AD15 -> 8827.4 | O3: ='[9]Income Statement'!AE20+'[9]Income Statement'!AE17+'[9]Income Statement'!AE15 -> 9644.4 | R3: Sun | S3: =(F34-B34)/B34 -> 0.41423184 | T3: =(F34/B34)^(1/5)-1 -> 0.071776232
A4: Net Profit | B4: ='[9]Income Statement'!B21 -> 1376.54 | C4: ='[9]Income Statement'!C21 -> 1984.29 | D4: ='[9]Income Statement'!D21 -> 2960.45 | E4: ='[9]Income Statement'!E21 -> 1823.38 | F4: ='[9]Income Statement'!F21 -> 1600 | G4: ='[9]Income Statement'!G21 -> 2191 | I4: Net Profit | J4: ='[9]Income Statement'!Z26 -> 2026 | K4: ='[9]Income Statement'!AA26 -> 1951.6 | L4: ='[9]Income Statement'!AB26 -> 2182.5 | M4: ='[9]Income Statement'!AC26 -> 4507.3 | N4: ='[9]Income Statement'!AD26 -> 5577.9 | O4: ='[9]Income Statement'!AE26 -> 5725.2 | R4: Mankind | S4: =(F53-B53)/B53 -> 1.1786749 | T4: =(F53/B53)^(1/5)-1 -> 0.16852628
A5: EBITDA Margin | B5: =B3/B2 -> 0.36027614 | C5: =C3/C2 -> 0.41560248 | D5: =D3/D2 -> 0.44037273 | E5: =E3/E2 -> 0.33437169 | F5: =F3/F2 -> 0.31085044 | G5: =G3/G2 -> 0.34184514 | I5: EBITDA Margin | J5: =J3/J2 -> 0.17041946 | K5: =K3/K2 -> 0.2151777 | L5: =L3/L2 -> 0.19301758 | M5: =M3/M2 -> 0.28783061 | N5: =N3/N2 -> 0.3053893 | O5: =O3/O2 -> 0.28583453 | R5: Reddy's | S5: =(N15-J15)/J15 -> 0.42055822 | T5: =(N15/J15)^(1/5)-1 -> 0.072733411
A6: Net Profit Margin | B6: =B4/B2 -> 0.24651284 | C6: =C4/C2 -> 0.28218164 | D6: =D4/D2 -> 0.32626712 | E6: =E4/E2 -> 0.22477093 | F6: =F4/F2 -> 0.19550342 | G6: =G4/G2 -> 0.2255972 | I6: Net Profit Margin | J6: =J4/J2 -> 0.11170166 | K6: =K4/K2 -> 0.10091577 | L6: =L4/L2 -> 0.09907125 | M6: =M4/M2 -> 0.17520952 | N6: =N4/N2 -> 0.19297086 | O6: =O4/O2 -> 0.1696798 | R6: Torrent | S6: =(N34-J34)/J34 -> 0.25485485 | T6: =(N34/J34)^(1/5)-1 -> 0.046450521
A7: R&D expense ratio | B7: ='[9]Ratio Analysis'!B25 -> 0.0091797172 | C7: ='[9]Ratio Analysis'!C25 -> 0.07289575 | D7: ='[9]Ratio Analysis'!D25 -> 0.022813185 | E7: ='[9]Ratio Analysis'!E25 -> 0.028475735 | F7: ='[9]Ratio Analysis'!F25 -> 0.034934018 | G7: ='[9]Ratio Analysis'!G25 -> 0.024299835 | I7: R&D expense ratio | J7: ='[9]Ratio Analysis'!Z25 -> 0.084961627 | K7: ='[9]Ratio Analysis'!AA25 -> 0.085532269 | L7: ='[9]Ratio Analysis'!AB25 -> 0.079356865 | M7: ='[9]Ratio Analysis'!AC25 -> 0.075338579 | N7: ='[9]Ratio Analysis'!AD25 -> 0.079130543 | O7: ='[9]Ratio Analysis'!AE25 -> 0.081147084 | R7: Cipla | S7: =(N53-J53)/J53 -> -0.15851917 | T7: =(N53/J53)^(1/5)-1 -> -0.033929445
A8: Export Revenue ratio | B8: ='[9]Ratio Analysis'!B26 -> 0.81063207 | C8: ='[9]Ratio Analysis'!C26 -> 0.88 | D8: ='[9]Ratio Analysis'!D26 -> 0.9 | E8: ='[9]Ratio Analysis'!E26 -> 0.88 | F8: ='[9]Ratio Analysis'!F26 -> 0.87 | G8: ='[9]Ratio Analysis'!G26 -> 0.86 | I8: Export Revenue ratio | J8: ='[9]Ratio Analysis'!Z26 -> 0.834 | K8: ='[9]Ratio Analysis'!AA26 -> 0.8 | L8: ='[9]Ratio Analysis'!AB26 -> 0.69 | M8: ='[9]Ratio Analysis'!AC26 -> 0.79 | N8: ='[9]Ratio Analysis'!AD26 -> 0.834 | O8: ='[9]Ratio Analysis'!AE26 -> 0.835 | S8: =AVERAGE(S2:S7) -> 0.41996373 | T8: =AVERAGE(T2:T7) -> 0.066114713
A9: ROE | B9: ='[9]Ratio Analysis'!B10 -> 0.18831123 | C9: ='[9]Ratio Analysis'!C10 -> 0.21348825 | D9: ='[9]Ratio Analysis'!D10 -> 0.25242194 | E9: ='[9]Ratio Analysis'!E10 -> 0.14281876 | F9: ='[9]Ratio Analysis'!F10 -> 0.11789846 | G9: ='[9]Ratio Analysis'!G10 -> 0.14636916 | I9: ROE | J9: ='[9]Ratio Analysis'!Z10 -> 1.2933626 | K9: ='[9]Ratio Analysis'!AA10 -> 1.2397684 | L9: ='[9]Ratio Analysis'!AB10 -> 1.2487232 | M9: ='[9]Ratio Analysis'!AC10 -> 1.3389894 | N9: ='[9]Ratio Analysis'!AD10 -> 1.0230262 | O9: ='[9]Ratio Analysis'!AE10 -> 0.99451181
A10: Debt to Equity | B10: ='[9]Ratio Analysis'!B16 -> 0.0053146956 | C10: ='[9]Ratio Analysis'!C16 -> 0.00051965602 | D10: ='[9]Ratio Analysis'!D16 -> 0.00031462682 | E10: ='[9]Ratio Analysis'!E16 -> 0.00025534401 | F10: ='[9]Ratio Analysis'!F16 -> 0.00022105961 | G10: ='[9]Ratio Analysis'!G16 -> 0.00026721892 | I10: Debt to Equity | J10: ='[9]Ratio Analysis'!Z16 -> 0.24406714 | K10: ='[9]Ratio Analysis'!AA16 -> 0.11434213 | L10: ='[9]Ratio Analysis'!AB16 -> 0.16690002 | M10: ='[9]Ratio Analysis'!AC16 -> 0.17086881 | N10: ='[9]Ratio Analysis'!AD16 -> 0.070855218 | O10: ='[9]Ratio Analysis'!AE16 -> 0.13784139
A12: Forecasts | B12: 2026 | C12: 2027 | D12: 2028 | E12: 2029 | F12: 2030 | I12: Forecasts | J12: 2026 | K12: 2027 | L12: 2028 | M12: 2029 | N12: 2030
A13: Revenue | B13: ='[9]Income Statement Forecast'!B5 -> 10264.451 | C13: ='[9]Income Statement Forecast'!C5 -> 11256.3 | D13: ='[9]Income Statement Forecast'!D5 -> 12343.989 | E13: ='[9]Income Statement Forecast'!E5 -> 13536.782 | F13: ='[9]Income Statement Forecast'!F5 -> 14844.833 | I13: Revenue | J13: ='[9]Income Statement Forecast'!W7 -> 37419.188 | K13: ='[9]Income Statement Forecast'!X7 -> 41498.198 | L13: ='[9]Income Statement Forecast'!Y7 -> 46021.964 | M13: ='[9]Income Statement Forecast'!Z7 -> 51038.992 | N13: ='[9]Income Statement Forecast'!AA7 -> 56603.076
A14: EBITDA | B14: =[9]!Table31[[#This Row],[2026]] -> #REF! | C14: =[9]!Table31[[#This Row],[2027]] -> #REF! | D14: =[9]!Table31[[#This Row],[2028]] -> #REF! | E14: =[9]!Table31[[#This Row],[2029]] -> #REF! | F14: =[9]!Table31[[#This Row],[2030]] -> #REF! | I14: EBITDA | J14: =[9]!Table34[[#This Row],[2026]] -> 8145.0945 | K14: =[9]!Table34[[#This Row],[2027]] -> #REF! | L14: =[9]!Table34[[#This Row],[2028]] -> #REF! | M14: =[9]!Table34[[#This Row],[2029]] -> #REF! | N14: =[9]!Table34[[#This Row],[2030]] -> #REF!
A15: Net Profit | B15: ='[9]Income Statement Forecast'!B20 -> 2380.5325 | C15: ='[9]Income Statement Forecast'!C20 -> 2589.5902 | D15: ='[9]Income Statement Forecast'!D20 -> 2820.5626 | E15: ='[9]Income Statement Forecast'!E20 -> 3075.4626 | F15: ='[9]Income Statement Forecast'!F20 -> 3356.5075 | I15: Net Profit | J15: ='[9]Income Statement Forecast'!W20 -> 4063.0566 | K15: ='[9]Income Statement Forecast'!X20 -> 4411.8729 | L15: ='[9]Income Statement Forecast'!Y20 -> 4810.4398 | M15: ='[9]Income Statement Forecast'!Z20 -> 5262.3447 | N15: ='[9]Income Statement Forecast'!AA20 -> 5771.8085
A16: EBITDA Margin | B16: =B14/B13 -> #REF! | C16: =C14/C13 -> #REF! | D16: =D14/D13 -> #REF! | E16: =E14/E13 -> #REF! | F16: =F14/F13 -> #REF! | I16: EBITDA Margin | J16: =J14/J13 -> 0.2176716 | K16: =K14/K13 -> #REF! | L16: =L14/L13 -> #REF! | M16: =M14/M13 -> #REF! | N16: =N14/N13 -> #REF!
A17: Net Profit Margin | B17: =B15/B13 -> 0.23192009 | C17: =C15/C13 -> 0.23005697 | D17: =D15/D13 -> 0.22849684 | E17: =E15/E13 -> 0.22719304 | F17: =F15/F13 -> 0.22610611 | I17: Net Profit Margin | J17: =J15/J13 -> 0.10858217 | K17: =K15/K13 -> 0.10631481 | L17: =L15/L13 -> 0.10452487 | M17: =M15/M13 -> 0.1031044 | N17: =N15/N13 -> 0.10196987
A18: R&D expense ratio | B18: ='[9]Income Statement Forecast'!$B$11/'[9]Income Statement Forecast'!$B$7 -> 0.032099707 | C18: ='[9]Income Statement Forecast'!$B$11/'[9]Income Statement Forecast'!$B$7 -> 0.032099707 | D18: ='[9]Income Statement Forecast'!$B$11/'[9]Income Statement Forecast'!$B$7 -> 0.032099707 | E18: ='[9]Income Statement Forecast'!$B$11/'[9]Income Statement Forecast'!$B$7 -> 0.032099707 | F18: ='[9]Income Statement Forecast'!$B$11/'[9]Income Statement Forecast'!$B$7 -> 0.032099707 | I18: R&D expense ratio | J18: ='[9]Income Statement Forecast'!W11/'[9]Income Statement Forecast'!W7 -> 0.078302055 | K18: ='[9]Income Statement Forecast'!X11/'[9]Income Statement Forecast'!X7 -> 0.078324086 | L18: ='[9]Income Statement Forecast'!Y11/'[9]Income Statement Forecast'!Y7 -> 0.078345936 | M18: ='[9]Income Statement Forecast'!Z11/'[9]Income Statement Forecast'!Z7 -> 0.078367608 | N18: ='[9]Income Statement Forecast'!AA11/'[9]Income Statement Forecast'!AA7 -> 0.078389103
A20: KPI | B20: 2020 | C20: 2021 | D20: 2022 | E20: 2023 | F20: 2024 | G20: 2025 | I20: KPI | J20: 2020 | K20: 2021 | L20: 2022 | M20: 2023 | N20: 2024 | O20: 2025
A21: Revenue | B21: ='[9]Income Statement'!J7 -> 33473.48 | C21: ='[9]Income Statement'!K7 -> 34333.66 | D21: ='[9]Income Statement'!L7 -> 39576 | E21: ='[9]Income Statement'!M7 -> 44520.2 | F21: ='[9]Income Statement'!N7 -> 49851.04 | G21: ='[9]Income Statement'!O7 -> 54543.48 | I21: Revenue | J21: ='[9]Income Statement'!AH7 -> 8060.61 | K21: ='[9]Income Statement'!AI7 -> 8061.48 | L21: ='[9]Income Statement'!AJ7 -> 8704.6 | M21: ='[9]Income Statement'!AK7 -> 9665.29 | N21: ='[9]Income Statement'!AL7 -> 10785.75 | O21: ='[9]Income Statement'!AM7 -> 11539.36
A22: EBITDA | B22: ='[9]Income Statement'!J18+'[9]Income Statement'!J13+'[9]Income Statement'!J14 -> 7625.74 | C22: ='[9]Income Statement'!K18+'[9]Income Statement'!K13+'[9]Income Statement'!K14 -> 9326.89 | D22: ='[9]Income Statement'!L18+'[9]Income Statement'!L13+'[9]Income Statement'!L14 -> 11319.23 | E22: ='[9]Income Statement'!M18+'[9]Income Statement'!M13+'[9]Income Statement'!M14 -> 12281.31 | F22: ='[9]Income Statement'!N18+'[9]Income Statement'!N13+'[9]Income Statement'!N14 -> 14377.32 | G22: ='[9]Income Statement'!O18+'[9]Income Statement'!O13+'[9]Income Statement'!O14 -> 17236.73 | I22: EBITDA | J22: ='[9]Income Statement'!AH17+'[9]Income Statement'!AH13+'[9]Income Statement'!AH14 -> 2291.66 | K22: ='[9]Income Statement'!AI17+'[9]Income Statement'!AI13+'[9]Income Statement'!AI14 -> 2542.33 | L22: ='[9]Income Statement'!AJ17+'[9]Income Statement'!AJ13+'[9]Income Statement'!AJ14 -> 2627.83 | M22: ='[9]Income Statement'!AK17+'[9]Income Statement'!AK13+'[9]Income Statement'!AK14 -> 2887.19 | N22: ='[9]Income Statement'!AL17+'[9]Income Statement'!AL13+'[9]Income Statement'!AL14 -> 3425.56 | O22: ='[9]Income Statement'!AM17+'[9]Income Statement'!AM13+'[9]Income Statement'!AM14 -> 3744.26
A23: Net Profit | B23: ='[9]Income Statement'!J30 -> 3764.93 | C23: ='[9]Income Statement'!K30 -> 2903.82 | D23: ='[9]Income Statement'!L30 -> 3272.73 | E23: ='[9]Income Statement'!M30 -> 8473.58 | F23: ='[9]Income Statement'!N30 -> 9576.38 | G23: ='[9]Income Statement'!O30 -> 10929.04 | I23: Net Profit | J23: ='[9]Income Statement'!AH25 -> 1024.72 | K23: ='[9]Income Statement'!AI25 -> 1251.88 | L23: ='[9]Income Statement'!AJ25 -> 777.18 | M23: ='[9]Income Statement'!AK25 -> 1245.23 | N23: ='[9]Income Statement'!AL25 -> 1656.38 | O23: ='[9]Income Statement'!AM25 -> 1911.25
A24: EBITDA Margin | B24: =B22/B21 -> 0.22781438 | C24: =C22/C21 -> 0.27165441 | D24: =D22/D21 -> 0.28601248 | E24: =E22/E21 -> 0.27585927 | F24: =F22/F21 -> 0.28840562 | G24: =G22/G21 -> 0.31601816 | I24: EBITDA Margin | J24: =J22/J21 -> 0.28430355 | K24: =K22/K21 -> 0.31536765 | L24: =L22/L21 -> 0.30188981 | M24: =M22/M21 -> 0.29871737 | N24: =N22/N21 -> 0.31760054 | O24: =O22/O21 -> 0.32447727
A25: Net Profit Margin | B25: =B23/B21 -> 0.11247501 | C25: =C23/C21 -> 0.084576477 | D25: =D23/D21 -> 0.082694815 | E25: =E23/E21 -> 0.19033113 | F25: =F23/F21 -> 0.1920999 | G25: =G23/G21 -> 0.20037299 | I25: Net Profit Margin | J25: =J23/J21 -> 0.12712686 | K25: =K23/K21 -> 0.15529158 | L25: =L23/L21 -> 0.089283827 | M25: =M23/M21 -> 0.12883524 | N25: =N23/N21 -> 0.15357115 | O25: =O23/O21 -> 0.16562877
A26: R&D expense ratio | B26: ='[9]Ratio Analysis'!J25 -> 0.068785797 | C26: ='[9]Ratio Analysis'!K25 -> 0.062617851 | D26: ='[9]Ratio Analysis'!L25 -> 0.056094603 | E26: ='[9]Ratio Analysis'!M25 -> 0.053180354 | F26: ='[9]Ratio Analysis'!N25 -> 0.065013689 | G26: ='[9]Ratio Analysis'!O25 -> 0.059556156 | I26: R&D expense ratio | J26: ='[9]Ratio Analysis'!AH25 -> 0.047254488 | K26: ='[9]Ratio Analysis'!AI25 -> 0.060410743 | L26: ='[9]Ratio Analysis'!AJ25 -> 0.059279002 | M26: ='[9]Ratio Analysis'!AK25 -> 0.053386913 | N26: ='[9]Ratio Analysis'!AL25 -> 0.047 | O26: ='[9]Ratio Analysis'!AM25 -> 0.050349413
A27: Export Revenue ratio | B27: ='[9]Ratio Analysis'!J26 -> 0.12561452 | C27: ='[9]Ratio Analysis'!K26 -> 0.68 | D27: ='[9]Ratio Analysis'!L26 -> 0.48 | E27: ='[9]Ratio Analysis'!M26 -> 0.689 | F27: ='[9]Ratio Analysis'!N26 -> 0.727 | G27: ='[9]Ratio Analysis'!O26 -> 0.7 | I27: Export Revenue ratio | J27: ='[9]Ratio Analysis'!AH26 -> 0.54859372 | K27: ='[9]Ratio Analysis'!AI26 -> 0.53426914 | L27: ='[9]Ratio Analysis'!AJ26 -> 0.45 | M27: ='[9]Ratio Analysis'!AK26 -> 0.41 | N27: ='[9]Ratio Analysis'!AL26 -> 0.425 | O27: ='[9]Ratio Analysis'!AM26 -> 0.24
A28: ROE | B28: ='[9]Ratio Analysis'!J10 -> 0.07664028 | C28: ='[9]Ratio Analysis'!K10 -> 0.058686944 | D28: ='[9]Ratio Analysis'!L10 -> 0.133103 | E28: ='[9]Ratio Analysis'!M10 -> 0.35680695 | F28: ='[9]Ratio Analysis'!N10 -> 0.14266288 | G28: ='[9]Ratio Analysis'!O10 -> 0.1507746 | I28: ROE | J28: ='[9]Ratio Analysis'!AH10 -> 0.21245558 | K28: ='[9]Ratio Analysis'!AI10 -> 0.21446694 | L28: ='[9]Ratio Analysis'!AJ10 -> 0.13055376 | M28: ='[9]Ratio Analysis'!AK10 -> 0.20090609 | N28: ='[9]Ratio Analysis'!AL10 -> 0.2415904 | O28: ='[9]Ratio Analysis'!AM10 -> 0.2517887
A29: Debt to Equity | B29: ='[9]Ratio Analysis'!J16 -> 0.15426662 | C29: ='[9]Ratio Analysis'!K16 -> 0.06756349 | D29: ='[9]Ratio Analysis'!L16 -> 0.20636287 | E29: ='[9]Ratio Analysis'!M16 -> 0.32805718 | F29: ='[9]Ratio Analysis'!N16 -> 0.050431622 | G29: ='[9]Ratio Analysis'!O16 -> 0.034096125 | I29: Debt to Equity | J29: ='[9]Ratio Analysis'!AH16 -> 0.90521892 | K29: ='[9]Ratio Analysis'!AI16 -> 0.62452695 | L29: ='[9]Ratio Analysis'!AJ16 -> 0.68363584 | M29: ='[9]Ratio Analysis'!AK16 -> 0.8661664 | N29: ='[9]Ratio Analysis'!AL16 -> 0.58661785 | O29: ='[9]Ratio Analysis'!AM16 -> 0.42187469
A31: Forecasts | B31: 2026 | C31: 2027 | D31: 2028 | E31: 2029 | F31: 2030 | I31: Forecasts | J31: 2026 | K31: 2027 | L31: 2028 | M31: 2029 | N31: 2030
